Traceback (most recent call last):
  File "C:\ProgramData\Anaconda3\lib\site-packages\jupyter_cache\executors\utils.py", line 51, in single_nb_execution
    executenb(
  File "C:\ProgramData\Anaconda3\lib\site-packages\nbclient\client.py", line 1112, in execute
    return NotebookClient(nb=nb, resources=resources, km=km, **kwargs).execute()
  File "C:\ProgramData\Anaconda3\lib\site-packages\nbclient\util.py", line 74, in wrapped
    return just_run(coro(*args, **kwargs))
  File "C:\ProgramData\Anaconda3\lib\site-packages\nbclient\util.py", line 53, in just_run
    return loop.run_until_complete(coro)
  File "C:\ProgramData\Anaconda3\lib\asyncio\base_events.py", line 642, in run_until_complete
    return future.result()
  File "C:\ProgramData\Anaconda3\lib\site-packages\nbclient\client.py", line 553, in async_execute
    await self.async_execute_cell(
  File "C:\ProgramData\Anaconda3\lib\site-packages\nbclient\client.py", line 857, in async_execute_cell
    self._check_raise_for_error(cell, exec_reply)
  File "C:\ProgramData\Anaconda3\lib\site-packages\nbclient\client.py", line 760, in _check_raise_for_error
    raise CellExecutionError.from_cell_and_msg(cell, exec_reply_content)
nbclient.exceptions.CellExecutionError: An error occurred while executing the following cell:
------------------
import plotly.express as px
import numpy as np

import plotly.io as pio
pio.renderers.default = "inline"
------------------

[1;31m---------------------------------------------------------------------------[0m
[1;31mValueError[0m                                Traceback (most recent call last)
[1;32m~\AppData\Local\Temp/ipykernel_9872/33437994.py[0m in [0;36m<module>[1;34m[0m
[0;32m      3[0m [1;33m[0m[0m
[0;32m      4[0m [1;32mimport[0m [0mplotly[0m[1;33m.[0m[0mio[0m [1;32mas[0m [0mpio[0m[1;33m[0m[1;33m[0m[0m
[1;32m----> 5[1;33m [0mpio[0m[1;33m.[0m[0mrenderers[0m[1;33m.[0m[0mdefault[0m [1;33m=[0m [1;34m"inline"[0m[1;33m[0m[1;33m[0m[0m
[0m
[1;32mC:\ProgramData\Anaconda3\lib\site-packages\plotly\io\_renderers.py[0m in [0;36mdefault[1;34m(self, value)[0m
[0;32m    151[0m [1;33m[0m[0m
[0;32m    152[0m         [1;31m# Store defaults name and list of renderer(s)[0m[1;33m[0m[1;33m[0m[0m
[1;32m--> 153[1;33m         [0mrenderer_names[0m [1;33m=[0m [0mself[0m[1;33m.[0m[0m_validate_coerce_renderers[0m[1;33m([0m[0mvalue[0m[1;33m)[0m[1;33m[0m[1;33m[0m[0m
[0m[0;32m    154[0m         [0mself[0m[1;33m.[0m[0m_default_name[0m [1;33m=[0m [0mvalue[0m[1;33m[0m[1;33m[0m[0m
[0;32m    155[0m         [0mself[0m[1;33m.[0m[0m_default_renderers[0m [1;33m=[0m [1;33m[[0m[0mself[0m[1;33m[[0m[0mname[0m[1;33m][0m [1;32mfor[0m [0mname[0m [1;32min[0m [0mrenderer_names[0m[1;33m][0m[1;33m[0m[1;33m[0m[0m

[1;32mC:\ProgramData\Anaconda3\lib\site-packages\plotly\io\_renderers.py[0m in [0;36m_validate_coerce_renderers[1;34m(self, renderers_string)[0m
[0;32m    218[0m         [0minvalid[0m [1;33m=[0m [1;33m[[0m[0mname[0m [1;32mfor[0m [0mname[0m [1;32min[0m [0mrenderer_names[0m [1;32mif[0m [0mname[0m [1;32mnot[0m [1;32min[0m [0mself[0m[1;33m][0m[1;33m[0m[1;33m[0m[0m
[0;32m    219[0m         [1;32mif[0m [0minvalid[0m[1;33m:[0m[1;33m[0m[1;33m[0m[0m
[1;32m--> 220[1;33m             raise ValueError(
[0m[0;32m    221[0m                 """
[0;32m    222[0m Invalid named renderer(s) received: {}""".format(

[1;31mValueError[0m: 
Invalid named renderer(s) received: ['inline']
ValueError: 
Invalid named renderer(s) received: ['inline']

