Traceback (most recent call last):
  File "/home/randall/anaconda3/envs/libro-ec4301/lib/python3.8/site-packages/jupyter_cache/executors/utils.py", line 51, in single_nb_execution
    executenb(
  File "/home/randall/anaconda3/envs/libro-ec4301/lib/python3.8/site-packages/nbclient/client.py", line 1112, in execute
    return NotebookClient(nb=nb, resources=resources, km=km, **kwargs).execute()
  File "/home/randall/anaconda3/envs/libro-ec4301/lib/python3.8/site-packages/nbclient/util.py", line 74, in wrapped
    return just_run(coro(*args, **kwargs))
  File "/home/randall/anaconda3/envs/libro-ec4301/lib/python3.8/site-packages/nbclient/util.py", line 53, in just_run
    return loop.run_until_complete(coro)
  File "/home/randall/anaconda3/envs/libro-ec4301/lib/python3.8/asyncio/base_events.py", line 616, in run_until_complete
    return future.result()
  File "/home/randall/anaconda3/envs/libro-ec4301/lib/python3.8/site-packages/nbclient/client.py", line 553, in async_execute
    await self.async_execute_cell(
  File "/home/randall/anaconda3/envs/libro-ec4301/lib/python3.8/site-packages/nbclient/client.py", line 857, in async_execute_cell
    self._check_raise_for_error(cell, exec_reply)
  File "/home/randall/anaconda3/envs/libro-ec4301/lib/python3.8/site-packages/nbclient/client.py", line 760, in _check_raise_for_error
    raise CellExecutionError.from_cell_and_msg(cell, exec_reply_content)
nbclient.exceptions.CellExecutionError: An error occurred while executing the following cell:
------------------
def correlogramas4(serie, residencia, func):
    fig, axs= plt.subplots(2,2, figsize=[12,5], sharex=True, sharey=True)
    opts = dict(lags=24)
    if func is plot_pacf:
        opts['method'] = 'ols'

    func(serie, **opts,ax=axs[0,0], title='$y_t$');
    func(serie.diff(1).dropna(), **opts, ax=axs[0,1],title='$\Delta y_t$');
    func(serie.diff(12).dropna(), **opts, ax=axs[1,0],title='$\Delta_{12}y_t$');
    func(serie.diff(1).diff(12).dropna(), **opts, ax=axs[1,1],title='$\Delta\Delta_{12}y_t$');

    for ax in axs.flat:
        ax.set(xlim=[-0.5,24.5], xticks=np.arange(0,25,6))

    pp = 'parcial' if (func is plot_pacf) else ''
    fig.suptitle(f'Correlogramas {pp} de cantidad de pasajeros {residencia} en SJO', size=18)
    return fig

extranjeros = pd.DataFrame(np.log(sjodatos['extranjeros'].values), index=pd.period_range('2011-01', '2019-12', freq='M'))
correlogramas4(extranjeros, 'extranjeros', plot_acf);
------------------

[0;31m---------------------------------------------------------------------------[0m
[0;31mNameError[0m                                 Traceback (most recent call last)
[0;32m<ipython-input-3-4a2237692328>[0m in [0;36m<module>[0;34m[0m
[1;32m     17[0m     [0;32mreturn[0m [0mfig[0m[0;34m[0m[0;34m[0m[0m
[1;32m     18[0m [0;34m[0m[0m
[0;32m---> 19[0;31m [0mextranjeros[0m [0;34m=[0m [0mpd[0m[0;34m.[0m[0mDataFrame[0m[0;34m([0m[0mnp[0m[0;34m.[0m[0mlog[0m[0;34m([0m[0msjodatos[0m[0;34m[[0m[0;34m'extranjeros'[0m[0;34m][0m[0;34m.[0m[0mvalues[0m[0;34m)[0m[0;34m,[0m [0mindex[0m[0;34m=[0m[0mpd[0m[0;34m.[0m[0mperiod_range[0m[0;34m([0m[0;34m'2011-01'[0m[0;34m,[0m [0;34m'2019-12'[0m[0;34m,[0m [0mfreq[0m[0;34m=[0m[0;34m'M'[0m[0;34m)[0m[0;34m)[0m[0;34m[0m[0;34m[0m[0m
[0m[1;32m     20[0m [0mcorrelogramas4[0m[0;34m([0m[0mextranjeros[0m[0;34m,[0m [0;34m'extranjeros'[0m[0;34m,[0m [0mplot_acf[0m[0;34m)[0m[0;34m;[0m[0;34m[0m[0;34m[0m[0m

[0;31mNameError[0m: name 'sjodatos' is not defined
NameError: name 'sjodatos' is not defined

