Traceback (most recent call last):
  File "C:\ProgramData\Anaconda3\envs\libro-ec4301\lib\site-packages\jupyter_cache\executors\utils.py", line 51, in single_nb_execution
    executenb(
  File "C:\ProgramData\Anaconda3\envs\libro-ec4301\lib\site-packages\nbclient\client.py", line 1204, in execute
    return NotebookClient(nb=nb, resources=resources, km=km, **kwargs).execute()
  File "C:\ProgramData\Anaconda3\envs\libro-ec4301\lib\site-packages\nbclient\util.py", line 84, in wrapped
    return just_run(coro(*args, **kwargs))
  File "C:\ProgramData\Anaconda3\envs\libro-ec4301\lib\site-packages\nbclient\util.py", line 62, in just_run
    return loop.run_until_complete(coro)
  File "C:\ProgramData\Anaconda3\envs\libro-ec4301\lib\asyncio\base_events.py", line 647, in run_until_complete
    return future.result()
  File "C:\ProgramData\Anaconda3\envs\libro-ec4301\lib\site-packages\nbclient\client.py", line 663, in async_execute
    await self.async_execute_cell(
  File "C:\ProgramData\Anaconda3\envs\libro-ec4301\lib\site-packages\nbclient\client.py", line 965, in async_execute_cell
    await self._check_raise_for_error(cell, cell_index, exec_reply)
  File "C:\ProgramData\Anaconda3\envs\libro-ec4301\lib\site-packages\nbclient\client.py", line 862, in _check_raise_for_error
    raise CellExecutionError.from_cell_and_msg(cell, exec_reply_content)
nbclient.exceptions.CellExecutionError: An error occurred while executing the following cell:
------------------
pd.options.plotting.backend = "plotly"

NP = pd.read_stata(''../../data/NelsonPlosserData.dta', index_col='year')
NP.index = NP.index.year

# modelo de salarios nominales
lwg = NP[['lwg']].dropna()
lwg['DL'] = (lwg.index > 1929).astype(int)
lwg['DP'] = (lwg.index == 1930).astype(int)
lwg['t'] = np.arange(lwg.shape[0])
lwg['Ly'] = lwg['lwg'].shift(1)
model1_lwg = ols('lwg~ DL + DP + t + Ly', lwg).fit()
model2_lwg = ols('lwg~ DL + t ', lwg).fit()

lwg['Ajuste'] = model2_lwg.fittedvalues

lwg[['lwg', 'Ajuste']].plot()

#title='Salarios nominales'
------------------

[1;36m  Input [1;32mIn [4][1;36m[0m
[1;33m    NP = pd.read_stata(''../../data/NelsonPlosserData.dta', index_col='year')[0m
[1;37m                          ^[0m
[1;31mSyntaxError[0m[1;31m:[0m invalid syntax

SyntaxError: invalid syntax (3648921078.py, line 3)

