Traceback (most recent call last):
  File "/home/randall/anaconda3/envs/libro-ec4301/lib/python3.8/site-packages/jupyter_cache/executors/utils.py", line 51, in single_nb_execution
    executenb(
  File "/home/randall/anaconda3/envs/libro-ec4301/lib/python3.8/site-packages/nbclient/client.py", line 1112, in execute
    return NotebookClient(nb=nb, resources=resources, km=km, **kwargs).execute()
  File "/home/randall/anaconda3/envs/libro-ec4301/lib/python3.8/site-packages/nbclient/util.py", line 74, in wrapped
    return just_run(coro(*args, **kwargs))
  File "/home/randall/anaconda3/envs/libro-ec4301/lib/python3.8/site-packages/nbclient/util.py", line 53, in just_run
    return loop.run_until_complete(coro)
  File "/home/randall/anaconda3/envs/libro-ec4301/lib/python3.8/asyncio/base_events.py", line 616, in run_until_complete
    return future.result()
  File "/home/randall/anaconda3/envs/libro-ec4301/lib/python3.8/site-packages/nbclient/client.py", line 553, in async_execute
    await self.async_execute_cell(
  File "/home/randall/anaconda3/envs/libro-ec4301/lib/python3.8/site-packages/nbclient/client.py", line 857, in async_execute_cell
    self._check_raise_for_error(cell, exec_reply)
  File "/home/randall/anaconda3/envs/libro-ec4301/lib/python3.8/site-packages/nbclient/client.py", line 760, in _check_raise_for_error
    raise CellExecutionError.from_cell_and_msg(cell, exec_reply_content)
nbclient.exceptions.CellExecutionError: An error occurred while executing the following cell:
------------------
xlag = np.zeros([2,1])
XpX = np.zeros([2,2])
XpY = np.zeros([2,2])

T = 4000
minT = 5
Xest = np.zeros([T+1, 4])

for t in range(T+1):
    x = Î¦ @ xlag + sigma * np.random.randn(2,1)
    XpX += np.outer(xlag, xlag)
    XpY += np.outer(xlag, x)
    xlag = x.copy()

    if t>minT:
        Xest[t] = np.linalg.solve(XpX/t, XpY/t).flatten()


estimates2 = pd.DataFrame(Xest[minT:], columns=param_names)

ax = estimates2.plot(color='b',figsize=[15,8],subplots=True, layout=[2,2])

for i in range(2):
    for j in range(2):
        ax[i,j].axhline(y=A[j,i],linewidth=1, color='r')
------------------

[0;31m---------------------------------------------------------------------------[0m
[0;31mNameError[0m                                 Traceback (most recent call last)
[0;32m<ipython-input-5-1ab3c15c1520>[0m in [0;36m<module>[0;34m[0m
[1;32m     23[0m [0;32mfor[0m [0mi[0m [0;32min[0m [0mrange[0m[0;34m([0m[0;36m2[0m[0;34m)[0m[0;34m:[0m[0;34m[0m[0;34m[0m[0m
[1;32m     24[0m     [0;32mfor[0m [0mj[0m [0;32min[0m [0mrange[0m[0;34m([0m[0;36m2[0m[0;34m)[0m[0;34m:[0m[0;34m[0m[0;34m[0m[0m
[0;32m---> 25[0;31m         [0max[0m[0;34m[[0m[0mi[0m[0;34m,[0m[0mj[0m[0;34m][0m[0;34m.[0m[0maxhline[0m[0;34m([0m[0my[0m[0;34m=[0m[0mA[0m[0;34m[[0m[0mj[0m[0;34m,[0m[0mi[0m[0;34m][0m[0;34m,[0m[0mlinewidth[0m[0;34m=[0m[0;36m1[0m[0;34m,[0m [0mcolor[0m[0;34m=[0m[0;34m'r'[0m[0;34m)[0m[0;34m[0m[0;34m[0m[0m
[0m
[0;31mNameError[0m: name 'A' is not defined
NameError: name 'A' is not defined

