Traceback (most recent call last):
  File "C:\ProgramData\Anaconda3\envs\libro-ec4301\lib\site-packages\nbclient\client.py", line 730, in _async_poll_for_reply
    msg = await ensure_async(self.kc.shell_channel.get_msg(timeout=new_timeout))
  File "C:\ProgramData\Anaconda3\envs\libro-ec4301\lib\site-packages\nbclient\util.py", line 96, in ensure_async
    result = await obj
  File "C:\ProgramData\Anaconda3\envs\libro-ec4301\lib\site-packages\jupyter_client\channels.py", line 230, in get_msg
    raise Empty
_queue.Empty

During handling of the above exception, another exception occurred:

Traceback (most recent call last):
  File "C:\ProgramData\Anaconda3\envs\libro-ec4301\lib\site-packages\jupyter_cache\executors\utils.py", line 51, in single_nb_execution
    executenb(
  File "C:\ProgramData\Anaconda3\envs\libro-ec4301\lib\site-packages\nbclient\client.py", line 1204, in execute
    return NotebookClient(nb=nb, resources=resources, km=km, **kwargs).execute()
  File "C:\ProgramData\Anaconda3\envs\libro-ec4301\lib\site-packages\nbclient\util.py", line 84, in wrapped
    return just_run(coro(*args, **kwargs))
  File "C:\ProgramData\Anaconda3\envs\libro-ec4301\lib\site-packages\nbclient\util.py", line 62, in just_run
    return loop.run_until_complete(coro)
  File "C:\ProgramData\Anaconda3\envs\libro-ec4301\lib\asyncio\base_events.py", line 647, in run_until_complete
    return future.result()
  File "C:\ProgramData\Anaconda3\envs\libro-ec4301\lib\site-packages\nbclient\client.py", line 663, in async_execute
    await self.async_execute_cell(
  File "C:\ProgramData\Anaconda3\envs\libro-ec4301\lib\site-packages\nbclient\client.py", line 949, in async_execute_cell
    exec_reply = await self.task_poll_for_reply
  File "C:\ProgramData\Anaconda3\envs\libro-ec4301\lib\site-packages\nbclient\client.py", line 754, in _async_poll_for_reply
    await self._async_handle_timeout(timeout, cell)
  File "C:\ProgramData\Anaconda3\envs\libro-ec4301\lib\site-packages\nbclient\client.py", line 801, in _async_handle_timeout
    raise CellTimeoutError.error_from_timeout_and_cell(
nbclient.exceptions.CellTimeoutError: A cell timed out while it was being executed, after 900 seconds.
The message was: Cell execution timed out.
Here is a preview of the cell contents:
-------------------
['%%time', 'def regresion(T=40):', '    e = np.random.randn(2, T)', '', '    df = pd.DataFrame(dict(']
...
['    ax.grid(False)', '', '    ', "plot_simulated('estacionaria', ax0)", "plot_simulated('espuria', ax1)"]
-------------------

