Traceback (most recent call last):
  File "C:\ProgramData\Anaconda3\envs\libro-ec4301\lib\site-packages\jupyter_cache\executors\utils.py", line 51, in single_nb_execution
    executenb(
  File "C:\ProgramData\Anaconda3\envs\libro-ec4301\lib\site-packages\nbclient\client.py", line 1204, in execute
    return NotebookClient(nb=nb, resources=resources, km=km, **kwargs).execute()
  File "C:\ProgramData\Anaconda3\envs\libro-ec4301\lib\site-packages\nbclient\util.py", line 84, in wrapped
    return just_run(coro(*args, **kwargs))
  File "C:\ProgramData\Anaconda3\envs\libro-ec4301\lib\site-packages\nbclient\util.py", line 62, in just_run
    return loop.run_until_complete(coro)
  File "C:\ProgramData\Anaconda3\envs\libro-ec4301\lib\asyncio\base_events.py", line 647, in run_until_complete
    return future.result()
  File "C:\ProgramData\Anaconda3\envs\libro-ec4301\lib\site-packages\nbclient\client.py", line 663, in async_execute
    await self.async_execute_cell(
  File "C:\ProgramData\Anaconda3\envs\libro-ec4301\lib\site-packages\nbclient\client.py", line 965, in async_execute_cell
    await self._check_raise_for_error(cell, cell_index, exec_reply)
  File "C:\ProgramData\Anaconda3\envs\libro-ec4301\lib\site-packages\nbclient\client.py", line 862, in _check_raise_for_error
    raise CellExecutionError.from_cell_and_msg(cell, exec_reply_content)
nbclient.exceptions.CellExecutionError: An error occurred while executing the following cell:
------------------
arma22 = ArmaProcess.from_coeffs(arcoefs=[1.3, -0.4], macoefs=[0.1, -0.3])
arma11 = ArmaProcess.from_coeffs(arcoefs=[0.8], macoefs=[0.6])

fig = make_subplots(rows=2, cols=2, subplot_titles=('ACF ARMA(2,2)','ACF ARMA(1,1)', 'PACF ARMA(2,2)','PACF ARMA(1,1)'))

graficar_autocorrelacion(fig, arma22, row=1, col=1)
graficar_autocorrelacion(fig, arma11, row=1, col=2)
graficar_autocorrelacion_parcial(fig, arma22, row=2, col=1)
graficar_autocorrelacion_parcial(fig, arma11, row=2, col=2)
fig.update_layout(**(opciones | dict(height=500)))
fig.show()
------------------

[1;31m---------------------------------------------------------------------------[0m
[1;31mNameError[0m                                 Traceback (most recent call last)
Input [1;32mIn [2][0m, in [0;36m<cell line: 6>[1;34m()[0m
[0;32m      2[0m arma11 [38;5;241m=[39m ArmaProcess[38;5;241m.[39mfrom_coeffs(arcoefs[38;5;241m=[39m[[38;5;241m0.8[39m], macoefs[38;5;241m=[39m[[38;5;241m0.6[39m])
[0;32m      4[0m fig [38;5;241m=[39m make_subplots(rows[38;5;241m=[39m[38;5;241m2[39m, cols[38;5;241m=[39m[38;5;241m2[39m, subplot_titles[38;5;241m=[39m([38;5;124m'[39m[38;5;124mACF ARMA(2,2)[39m[38;5;124m'[39m,[38;5;124m'[39m[38;5;124mACF ARMA(1,1)[39m[38;5;124m'[39m, [38;5;124m'[39m[38;5;124mPACF ARMA(2,2)[39m[38;5;124m'[39m,[38;5;124m'[39m[38;5;124mPACF ARMA(1,1)[39m[38;5;124m'[39m))
[1;32m----> 6[0m [43mgraficar_autocorrelacion[49m(fig, arma22, row[38;5;241m=[39m[38;5;241m1[39m, col[38;5;241m=[39m[38;5;241m1[39m)
[0;32m      7[0m graficar_autocorrelacion(fig, arma11, row[38;5;241m=[39m[38;5;241m1[39m, col[38;5;241m=[39m[38;5;241m2[39m)
[0;32m      8[0m graficar_autocorrelacion_parcial(fig, arma22, row[38;5;241m=[39m[38;5;241m2[39m, col[38;5;241m=[39m[38;5;241m1[39m)

[1;31mNameError[0m: name 'graficar_autocorrelacion' is not defined
NameError: name 'graficar_autocorrelacion' is not defined

