Traceback (most recent call last):
  File "/home/randall/anaconda3/envs/libro-ec4301/lib/python3.8/site-packages/jupyter_cache/executors/utils.py", line 51, in single_nb_execution
    executenb(
  File "/home/randall/anaconda3/envs/libro-ec4301/lib/python3.8/site-packages/nbclient/client.py", line 1112, in execute
    return NotebookClient(nb=nb, resources=resources, km=km, **kwargs).execute()
  File "/home/randall/anaconda3/envs/libro-ec4301/lib/python3.8/site-packages/nbclient/util.py", line 74, in wrapped
    return just_run(coro(*args, **kwargs))
  File "/home/randall/anaconda3/envs/libro-ec4301/lib/python3.8/site-packages/nbclient/util.py", line 53, in just_run
    return loop.run_until_complete(coro)
  File "/home/randall/anaconda3/envs/libro-ec4301/lib/python3.8/asyncio/base_events.py", line 616, in run_until_complete
    return future.result()
  File "/home/randall/anaconda3/envs/libro-ec4301/lib/python3.8/site-packages/nbclient/client.py", line 553, in async_execute
    await self.async_execute_cell(
  File "/home/randall/anaconda3/envs/libro-ec4301/lib/python3.8/site-packages/nbclient/client.py", line 857, in async_execute_cell
    self._check_raise_for_error(cell, exec_reply)
  File "/home/randall/anaconda3/envs/libro-ec4301/lib/python3.8/site-packages/nbclient/client.py", line 760, in _check_raise_for_error
    raise CellExecutionError.from_cell_and_msg(cell, exec_reply_content)
nbclient.exceptions.CellExecutionError: An error occurred while executing the following cell:
------------------
pib['t'] = np.arange(pib.shape[0])

res = smf.ols("lPIB ~ t", data=pib).fit()
res.summary().tables[1]

df = pd.concat([pib['lPIB'], res.fittedvalues, res.resid], axis=1)
df.columns = ["PIB", "Ajuste", "Residuos"]
df.index = df.index.to_timestamp() # para poder graficar con plotly

merge_plots(
  [df[["PIB", "Ajuste"]].plot(), df[["Residuos"]].plot()],
  subplot_titles=["PIB con tendencia lineal ajustada", "Residuos"],
  title_text=r"$\log\text{PIB}_t = c + at + \epsilon_{t}$",
)
------------------

[0;31m---------------------------------------------------------------------------[0m
[0;31mAttributeError[0m                            Traceback (most recent call last)
[0;32m<ipython-input-6-aa9738cefdab>[0m in [0;36m<module>[0;34m[0m
[1;32m      6[0m [0mdf[0m [0;34m=[0m [0mpd[0m[0;34m.[0m[0mconcat[0m[0;34m([0m[0;34m[[0m[0mpib[0m[0;34m[[0m[0;34m'lPIB'[0m[0;34m][0m[0;34m,[0m [0mres[0m[0;34m.[0m[0mfittedvalues[0m[0;34m,[0m [0mres[0m[0;34m.[0m[0mresid[0m[0;34m][0m[0;34m,[0m [0maxis[0m[0;34m=[0m[0;36m1[0m[0;34m)[0m[0;34m[0m[0;34m[0m[0m
[1;32m      7[0m [0mdf[0m[0;34m.[0m[0mcolumns[0m [0;34m=[0m [0;34m[[0m[0;34m"PIB"[0m[0;34m,[0m [0;34m"Ajuste"[0m[0;34m,[0m [0;34m"Residuos"[0m[0;34m][0m[0;34m[0m[0;34m[0m[0m
[0;32m----> 8[0;31m [0mdf[0m[0;34m.[0m[0mindex[0m [0;34m=[0m [0mdf[0m[0;34m.[0m[0mindex[0m[0;34m.[0m[0mto_timestamp[0m[0;34m([0m[0;34m)[0m [0;31m# para poder graficar con plotly[0m[0;34m[0m[0;34m[0m[0m
[0m[1;32m      9[0m [0;34m[0m[0m
[1;32m     10[0m merge_plots(

[0;31mAttributeError[0m: 'DatetimeIndex' object has no attribute 'to_timestamp'
AttributeError: 'DatetimeIndex' object has no attribute 'to_timestamp'

