Traceback (most recent call last):
  File "/home/randall/anaconda3/envs/libro-ec4301/lib/python3.8/site-packages/jupyter_cache/executors/utils.py", line 51, in single_nb_execution
    executenb(
  File "/home/randall/anaconda3/envs/libro-ec4301/lib/python3.8/site-packages/nbclient/client.py", line 1112, in execute
    return NotebookClient(nb=nb, resources=resources, km=km, **kwargs).execute()
  File "/home/randall/anaconda3/envs/libro-ec4301/lib/python3.8/site-packages/nbclient/util.py", line 74, in wrapped
    return just_run(coro(*args, **kwargs))
  File "/home/randall/anaconda3/envs/libro-ec4301/lib/python3.8/site-packages/nbclient/util.py", line 53, in just_run
    return loop.run_until_complete(coro)
  File "/home/randall/anaconda3/envs/libro-ec4301/lib/python3.8/asyncio/base_events.py", line 616, in run_until_complete
    return future.result()
  File "/home/randall/anaconda3/envs/libro-ec4301/lib/python3.8/site-packages/nbclient/client.py", line 553, in async_execute
    await self.async_execute_cell(
  File "/home/randall/anaconda3/envs/libro-ec4301/lib/python3.8/site-packages/nbclient/client.py", line 857, in async_execute_cell
    self._check_raise_for_error(cell, exec_reply)
  File "/home/randall/anaconda3/envs/libro-ec4301/lib/python3.8/site-packages/nbclient/client.py", line 760, in _check_raise_for_error
    raise CellExecutionError.from_cell_and_msg(cell, exec_reply_content)
nbclient.exceptions.CellExecutionError: An error occurred while executing the following cell:
------------------
granger = pd.DataFrame(np.zeros([3,3]), index = datos.columns.values, columns=datos.columns.values)
granger.index.name = 'Explicativa'
granger.columns.name = 'Dependiente'

for i in datos.columns:
    for j in datos.columns:
        temp =
        granger.loc[j, i] = res.test_causality(i, j).pvalue
granger.round(3)
------------------

[0;36m  File [0;32m"<ipython-input-5-5855f7e9d3a2>"[0;36m, line [0;32m7[0m
[0;31m    temp =[0m
[0m          ^[0m
[0;31mSyntaxError[0m[0;31m:[0m invalid syntax

SyntaxError: invalid syntax (<ipython-input-5-5855f7e9d3a2>, line 7)

