Traceback (most recent call last):
  File "C:\ProgramData\Anaconda3\envs\libro-ec4301\lib\site-packages\jupyter_cache\executors\utils.py", line 51, in single_nb_execution
    executenb(
  File "C:\ProgramData\Anaconda3\envs\libro-ec4301\lib\site-packages\nbclient\client.py", line 1204, in execute
    return NotebookClient(nb=nb, resources=resources, km=km, **kwargs).execute()
  File "C:\ProgramData\Anaconda3\envs\libro-ec4301\lib\site-packages\nbclient\util.py", line 84, in wrapped
    return just_run(coro(*args, **kwargs))
  File "C:\ProgramData\Anaconda3\envs\libro-ec4301\lib\site-packages\nbclient\util.py", line 62, in just_run
    return loop.run_until_complete(coro)
  File "C:\ProgramData\Anaconda3\envs\libro-ec4301\lib\asyncio\base_events.py", line 647, in run_until_complete
    return future.result()
  File "C:\ProgramData\Anaconda3\envs\libro-ec4301\lib\site-packages\nbclient\client.py", line 663, in async_execute
    await self.async_execute_cell(
  File "C:\ProgramData\Anaconda3\envs\libro-ec4301\lib\site-packages\nbclient\client.py", line 965, in async_execute_cell
    await self._check_raise_for_error(cell, cell_index, exec_reply)
  File "C:\ProgramData\Anaconda3\envs\libro-ec4301\lib\site-packages\nbclient\client.py", line 862, in _check_raise_for_error
    raise CellExecutionError.from_cell_and_msg(cell, exec_reply_content)
nbclient.exceptions.CellExecutionError: An error occurred while executing the following cell:
------------------
import numpy as np
import pandas as pd
pd.options.plotting.backend = "plotly"
from macrodemos.common_components import merge_plots


import pandas_datareader as pdr
------------------

[1;31m---------------------------------------------------------------------------[0m
[1;31mModuleNotFoundError[0m                       Traceback (most recent call last)
Input [1;32mIn [1][0m, in [0;36m<cell line: 4>[1;34m()[0m
[0;32m      2[0m [38;5;28;01mimport[39;00m [38;5;21;01mpandas[39;00m [38;5;28;01mas[39;00m [38;5;21;01mpd[39;00m
[0;32m      3[0m pd[38;5;241m.[39moptions[38;5;241m.[39mplotting[38;5;241m.[39mbackend [38;5;241m=[39m [38;5;124m"[39m[38;5;124mplotly[39m[38;5;124m"[39m
[1;32m----> 4[0m [38;5;28;01mfrom[39;00m [38;5;21;01mmacrodemos[39;00m[38;5;21;01m.[39;00m[38;5;21;01mcommon_components[39;00m [38;5;28;01mimport[39;00m merge_plots
[0;32m      7[0m [38;5;28;01mimport[39;00m [38;5;21;01mpandas_datareader[39;00m [38;5;28;01mas[39;00m [38;5;21;01mpdr[39;00m

[1;31mModuleNotFoundError[0m: No module named 'macrodemos'
ModuleNotFoundError: No module named 'macrodemos'

