Traceback (most recent call last):
  File "C:\ProgramData\Anaconda3\envs\libro-ec4301\lib\site-packages\jupyter_cache\executors\utils.py", line 51, in single_nb_execution
    executenb(
  File "C:\ProgramData\Anaconda3\envs\libro-ec4301\lib\site-packages\nbclient\client.py", line 1204, in execute
    return NotebookClient(nb=nb, resources=resources, km=km, **kwargs).execute()
  File "C:\ProgramData\Anaconda3\envs\libro-ec4301\lib\site-packages\nbclient\util.py", line 84, in wrapped
    return just_run(coro(*args, **kwargs))
  File "C:\ProgramData\Anaconda3\envs\libro-ec4301\lib\site-packages\nbclient\util.py", line 62, in just_run
    return loop.run_until_complete(coro)
  File "C:\ProgramData\Anaconda3\envs\libro-ec4301\lib\asyncio\base_events.py", line 647, in run_until_complete
    return future.result()
  File "C:\ProgramData\Anaconda3\envs\libro-ec4301\lib\site-packages\nbclient\client.py", line 663, in async_execute
    await self.async_execute_cell(
  File "C:\ProgramData\Anaconda3\envs\libro-ec4301\lib\site-packages\nbclient\client.py", line 965, in async_execute_cell
    await self._check_raise_for_error(cell, cell_index, exec_reply)
  File "C:\ProgramData\Anaconda3\envs\libro-ec4301\lib\site-packages\nbclient\client.py", line 862, in _check_raise_for_error
    raise CellExecutionError.from_cell_and_msg(cell, exec_reply_content)
nbclient.exceptions.CellExecutionError: An error occurred while executing the following cell:
------------------
KPSS_una_serie('Real GNP', 'c')
------------------

[1;31m---------------------------------------------------------------------------[0m
[1;31mTypeError[0m                                 Traceback (most recent call last)
Input [1;32mIn [7][0m, in [0;36m<cell line: 1>[1;34m()[0m
[1;32m----> 1[0m [43mKPSS_una_serie[49m[43m([49m[38;5;124;43m'[39;49m[38;5;124;43mReal GNP[39;49m[38;5;124;43m'[39;49m[43m,[49m[43m [49m[38;5;124;43m'[39;49m[38;5;124;43mc[39;49m[38;5;124;43m'[39;49m[43m)[49m

Input [1;32mIn [6][0m, in [0;36mKPSS_una_serie[1;34m(nombre_variable, tipo)[0m
[0;32m      1[0m [38;5;28;01mdef[39;00m [38;5;21mKPSS_una_serie[39m(nombre_variable, tipo):
[0;32m      2[0m     [38;5;124;03m"""[39;00m
[0;32m      3[0m [38;5;124;03m    Calcula los estadÃ­sticos LM de la prueba de estacionariedad KPSS, con rezagos de 0 a 8[39;00m
[0;32m      4[0m [38;5;124;03m     [39;00m
[1;32m   (...)[0m
[0;32m     10[0m [38;5;124;03m        np.array, los 9 estadÃ­sticos LM estimados[39;00m
[0;32m     11[0m [38;5;124;03m    """[39;00m
[1;32m---> 12[0m     [38;5;28;01mreturn[39;00m [kpss(datos[nombre_variable][38;5;241m.[39mdropna(), regression[38;5;241m=[39mtipo, lags[38;5;241m=[39mk)[[38;5;241m0[39m] [38;5;28;01mfor[39;00m k [38;5;129;01min[39;00m [38;5;28mrange[39m([38;5;241m9[39m)]

Input [1;32mIn [6][0m, in [0;36m<listcomp>[1;34m(.0)[0m
[0;32m      1[0m [38;5;28;01mdef[39;00m [38;5;21mKPSS_una_serie[39m(nombre_variable, tipo):
[0;32m      2[0m     [38;5;124;03m"""[39;00m
[0;32m      3[0m [38;5;124;03m    Calcula los estadÃ­sticos LM de la prueba de estacionariedad KPSS, con rezagos de 0 a 8[39;00m
[0;32m      4[0m [38;5;124;03m     [39;00m
[1;32m   (...)[0m
[0;32m     10[0m [38;5;124;03m        np.array, los 9 estadÃ­sticos LM estimados[39;00m
[0;32m     11[0m [38;5;124;03m    """[39;00m
[1;32m---> 12[0m     [38;5;28;01mreturn[39;00m [[43mkpss[49m[43m([49m[43mdatos[49m[43m[[49m[43mnombre_variable[49m[43m][49m[38;5;241;43m.[39;49m[43mdropna[49m[43m([49m[43m)[49m[43m,[49m[43m [49m[43mregression[49m[38;5;241;43m=[39;49m[43mtipo[49m[43m,[49m[43m [49m[43mlags[49m[38;5;241;43m=[39;49m[43mk[49m[43m)[49m[[38;5;241m0[39m] [38;5;28;01mfor[39;00m k [38;5;129;01min[39;00m [38;5;28mrange[39m([38;5;241m9[39m)]

[1;31mTypeError[0m: kpss() got an unexpected keyword argument 'lags'
TypeError: kpss() got an unexpected keyword argument 'lags'

