Traceback (most recent call last):
  File "C:\ProgramData\Anaconda3\envs\libro-ec4301\lib\site-packages\jupyter_cache\executors\utils.py", line 51, in single_nb_execution
    executenb(
  File "C:\ProgramData\Anaconda3\envs\libro-ec4301\lib\site-packages\nbclient\client.py", line 1204, in execute
    return NotebookClient(nb=nb, resources=resources, km=km, **kwargs).execute()
  File "C:\ProgramData\Anaconda3\envs\libro-ec4301\lib\site-packages\nbclient\util.py", line 84, in wrapped
    return just_run(coro(*args, **kwargs))
  File "C:\ProgramData\Anaconda3\envs\libro-ec4301\lib\site-packages\nbclient\util.py", line 62, in just_run
    return loop.run_until_complete(coro)
  File "C:\ProgramData\Anaconda3\envs\libro-ec4301\lib\asyncio\base_events.py", line 647, in run_until_complete
    return future.result()
  File "C:\ProgramData\Anaconda3\envs\libro-ec4301\lib\site-packages\nbclient\client.py", line 663, in async_execute
    await self.async_execute_cell(
  File "C:\ProgramData\Anaconda3\envs\libro-ec4301\lib\site-packages\nbclient\client.py", line 965, in async_execute_cell
    await self._check_raise_for_error(cell, cell_index, exec_reply)
  File "C:\ProgramData\Anaconda3\envs\libro-ec4301\lib\site-packages\nbclient\client.py", line 862, in _check_raise_for_error
    raise CellExecutionError.from_cell_and_msg(cell, exec_reply_content)
nbclient.exceptions.CellExecutionError: An error occurred while executing the following cell:
------------------
shake_it_off = open("shake-it-off.txt", 'r', encoding='utf-8').read()

print(shake_it_off)
------------------

[1;31m---------------------------------------------------------------------------[0m
[1;31mFileNotFoundError[0m                         Traceback (most recent call last)
Input [1;32mIn [20][0m, in [0;36m<cell line: 1>[1;34m()[0m
[1;32m----> 1[0m shake_it_off [38;5;241m=[39m [38;5;28;43mopen[39;49m[43m([49m[38;5;124;43m"[39;49m[38;5;124;43mshake-it-off.txt[39;49m[38;5;124;43m"[39;49m[43m,[49m[43m [49m[38;5;124;43m'[39;49m[38;5;124;43mr[39;49m[38;5;124;43m'[39;49m[43m,[49m[43m [49m[43mencoding[49m[38;5;241;43m=[39;49m[38;5;124;43m'[39;49m[38;5;124;43mutf-8[39;49m[38;5;124;43m'[39;49m[43m)[49m[38;5;241m.[39mread()
[0;32m      3[0m [38;5;28mprint[39m(shake_it_off)

[1;31mFileNotFoundError[0m: [Errno 2] No such file or directory: 'shake-it-off.txt'
FileNotFoundError: [Errno 2] No such file or directory: 'shake-it-off.txt'

